<?xml version="1.0" encoding="utf-8"?>
<sdf version='1.7'>
   <model name="rahal_robot">


<link name='base_footprint'>
     
    </link>
      <joint name='base_footprint_joint' type='fixed'>
      <parent>base_footprint</parent>
      <child>base_link</child>
      <pose>0 0 0 0 0 0</pose>
    </joint>


    <!-- Base Link -->
    <link name='base_link'>

      <pose relative_to='base_footprint'>0 0 0.05 0 0 0</pose>
      <inertial>
        <pose>0 0 0 0 0 0</pose>
        <mass>1.1439176852714</mass>
        <inertia>
          <ixx>0.446134400302526</ixx>
          <ixy>-2.18000480348373E-05</ixy>
          <ixz>0.0113470100455749</ixz>
          <iyy>0.985173237691484</iyy>
          <iyz>2.52721045797753E-06</iyz>
          <izz>1.332699788346</izz>
        </inertia>
      </inertial>
      <visual name='base_link_visual'>
        <pose>0 0 0 0 0 0</pose>
        <geometry>
          <mesh>
            <scale>1 1 1</scale>
            <uri>package://rahal_description/meshes/base_link.STL</uri>
          </mesh>
        </geometry>
        <material>
         <diffuse>0.2 0.2 0.2 1.0</diffuse>
        <ambient>0.2 0.2 0.2 1.0</ambient>
        </material>
      </visual>
      <collision name='base_link_collision'>
        <pose>0 0 0 0 0 0</pose>
        <geometry>
          <mesh>
            <scale>1 1 1</scale>
            <uri>package://rahal_description/meshes/base_link.STL</uri>
          </mesh>
        </geometry>
      </collision>
    </link>


    <link name="upper_Link">
  <pose relative_to="base_link">0 0 0 0 0 0</pose>
  
  <inertial>
    <pose>0 0 0 0 0 0</pose>
    <mass>0.166872826924751</mass>
    <inertia>
      <ixx>0.000489929792443678</ixx>
      <ixy>-7.74903089672872E-18</ixy>
      <ixz>2.30455917227275E-21</ixz>
      <iyy>0.00269350489980573</iyy>
      <iyz>1.16991430571828E-20</iyz>
      <izz>0.00318332344369813</izz>
    </inertia>
  </inertial>

  <visual name="upper_Link_visual">
    <pose>0 0 0 0 0 0</pose>
    <geometry>
      <mesh>
        <scale>1 1 1</scale>
        <uri>package://rahal_description/meshes/upper_Link.STL</uri>
      </mesh>
    </geometry>
    <material>
      <diffuse>1 1 1 1</diffuse>
      <ambient>1 1 1 1</ambient>
    </material>
  </visual>

  <collision name="upper_Link_collision">
    <pose>0 0 0 0 0 0</pose>
    <geometry>
      <mesh>
        <scale>1 1 1</scale>
        <uri>package://rahal_description/meshes/upper_Link.STL</uri>
      </mesh>
    </geometry>
  </collision>
</link>

<joint name="upper_joint" type="fixed">
  <pose>0 0 0 0 0 0</pose>
  <parent>base_link</parent>
  <child>upper_Link</child>

</joint>
<link name="arabian_link">
  <pose relative_to="base_link">0.005 -0.000888981559154955 -0.01 0 0 0</pose>
  
  <inertial>
    <pose>0 0 0 0 0 0</pose>
    <mass>0.00950204606844057</mass>
    <inertia>
      <ixx>2.22232620057898E-07</ixx>
      <ixy>-7.20010067600906E-10</ixy>
      <ixz>4.32123218517469E-08</ixz>
      <iyy>1.59736508017579E-07</iyy>
      <iyz>1.6967868671769E-09</iyz>
      <izz>1.38773174550699E-07</izz>
    </inertia>
  </inertial>

  <visual name="arabian_link_visual">
    <pose>0 0 0 0 0 0</pose>
    <geometry>
      <mesh>
        <scale>1 1 1</scale>
        <uri>package://rahal_description/meshes/arabian_link.STL</uri>
      </mesh>
    </geometry>
    <material>
      <diffuse>0.364705882352941 0.768627450980392 0.870588235294118 1</diffuse>
      <ambient>0.364705882352941 0.768627450980392 0.870588235294118 1</ambient>
    </material>
  </visual>

  <collision name="arabian_link_collision">
    <pose>0 0 0 0 0 0</pose>
    <geometry>
      <mesh>
        <scale>1 1 1</scale>
        <uri>package://rahal_description/meshes/arabian_link.STL</uri>
      </mesh>
    </geometry>
  </collision>
</link>

<joint name="arabian_joint" type="fixed">
  <pose>0 0 0 0 0 0</pose>
  <parent>base_link</parent>
  <child>arabian_link</child>

</joint>

<link name="logo">
  <pose relative_to="upper_Link">-0.06 0 0.16 0 0 3.14</pose>
  <inertial>
    <pose>0 0 0 0 0 0</pose>
    <mass>0.001</mass>
    <inertia>
      <ixx>0.00001</ixx>
      <ixy>0.0</ixy>
      <ixz>0.0</ixz>
      <iyy>0.00001</iyy>
      <iyz>0.0</iyz>
      <izz>0.00001</izz>
    </inertia>
  </inertial>
  <visual name="logo_visual">
    <pose>0 0 0 0 0 0</pose>
    <geometry>
      <box>
        <size>0.19 0.19 0.001</size>
      </box>
    </geometry>
    <material>
      <diffuse>1 1 1 1</diffuse>
      <ambient>1 1 1 1</ambient>
      <specular>1 1 1 1</specular>
      <pbr>
        <metal>
          <albedo_map>model://rahal_description/textures/logo.png</albedo_map>
        </metal>
      </pbr>
    </material>
  </visual>
  <collision name="logo_collision">
    <pose>-0.05 -0.05 0.16 0 0 1.57</pose>
    <geometry>
      <box>
        <size>0.19 0.19 0.001</size>
      </box>
    </geometry>
  </collision>
</link>
<joint name="logo_joint" type="fixed">
  <pose>0 0.0 0.0 0 0 0</pose>
  <parent>upper_Link</parent>
  <child>logo</child>

</joint>



    <!-- Front Left Wheel -->
    <link name='front_left_wheel'>
      <pose relative_to='base_link'>0.18279 0.243 -0.014153 0 0 0</pose> 
      <inertial>
        <pose>0 0 0 0 0 0</pose>
        <mass>0.260404298470105</mass>
        <inertia>
          <ixx>0.000768916188073183</ixx>
          <ixy>-3.91608887242284E-09</ixy>
          <ixz>-1.86122419709981E-08</ixz>
          <iyy>0.00137090251737553</iyy>
          <iyz>-4.72596045124545E-10</iyz>
          <izz>0.000769014346730516</izz>
        </inertia>
      </inertial>
      <visual name='front_left_wheel_visual'>
        <pose>0 0 0 0 0 0</pose>

        <geometry>
          <mesh>
            <scale>1 1 1</scale>
            <uri>package://rahal_description/meshes/front_left_wheel.STL</uri>
          </mesh>
        </geometry>
        <material>
          <diffuse>0.0 0.0 0.0 1.0</diffuse>
          <ambient>0.0 0.0 0.0 1.0</ambient>
        </material>
      </visual>
      <collision name='front_left_wheel_collision'>
        <pose>0 0 0 0 0 0</pose>
        <geometry>
          <mesh>
            <scale>1 1 1</scale>
            <uri>package://rahal_description/meshes/front_left_wheel.STL</uri>
          </mesh>
        </geometry>
      </collision>
    </link>

    <!-- Front Right Wheel -->
    <link name='front_right_wheel'>
      <pose relative_to='base_link'>0.18279 -0.243 -0.014153 0 0 0</pose>  
      <inertial>
        <pose>0 0 0 0 0 0</pose>
        <mass>0.260404298470105</mass>
        <inertia>
          <ixx>0.000768916188073183</ixx>
          <ixy>-3.91608887242284E-09</ixy>
          <ixz>-1.86122419709981E-08</ixz>
          <iyy>0.00137090251737553</iyy>
          <iyz>-4.72596045124545E-10</iyz>
          <izz>0.000769014346730516</izz>
        </inertia>
      </inertial>
      <visual name='front_right_wheel_visual'>

         <pose>0 0 0 0 0 0</pose>
     
        <geometry>
          <mesh>
            <scale>1 1 1</scale>
            <uri>package://rahal_description/meshes/front_right_wheel.STL</uri>
          </mesh>
        </geometry>
        <material>
          <diffuse>0.0 0.0 0.0 1.0</diffuse>
          <ambient>0.0 0.0 0.0 1.0</ambient>
        </material>
      </visual>
      <collision name='front_right_wheel_collision'>
        <pose>0 0 0 0 0 0</pose>
        <geometry>
          <mesh>
            <scale>1 1 1</scale>
            <uri>package://rahal_description/meshes/front_right_wheel.STL</uri>
          </mesh>
        </geometry>
      </collision>
    </link>

    <!-- Rear Left Wheel -->
    <link name='rear_left_wheel'>
      <pose relative_to='base_link'>-0.17721 0.243 -0.014153 0 0 0</pose>  
      <inertial>
        <pose>0 0 0 0 0 0</pose>
        <mass>0.260404298470105</mass>
        <inertia>
          <ixx>0.000768916188073183</ixx>
          <ixy>-3.91608887242284E-09</ixy>
          <ixz>-1.86122419709981E-08</ixz>
          <iyy>0.00137090251737553</iyy>
          <iyz>-4.72596045124545E-10</iyz>
          <izz>0.000769014346730516</izz>
        </inertia>
      </inertial>
      <visual name='rear_left_wheel_visual'>
              <pose>0 0 0 0 0 0</pose>

        <geometry>
          <mesh>
            <scale>1 1 1</scale>
            <uri>package://rahal_description/meshes/rear_left_wheel.STL</uri>
          </mesh>
        </geometry>
        <material>
          <diffuse>0.0 0.0 0.0 1.0</diffuse>
          <ambient>0.0 0.0 0.0 1.0</ambient>
        </material>
      </visual>
      <collision name='rear_left_wheel_collision'>
        <pose>0 0 0 0 0 0</pose>
        <geometry>
          <mesh>
            <scale>1 1 1</scale>
            <uri>package://rahal_description/meshes/rear_left_wheel.STL</uri>
          </mesh>
        </geometry>
      </collision>
    </link>

    <!-- Rear Right Wheel -->
    <link name='rear_right_wheel'>
      <pose relative_to='base_link'>-0.17721 -0.24281 -0.014153 0 0 0</pose>  
      <inertial>
        <pose>0 0 0 0 0 0</pose>
        <mass>0.260404298470105</mass>
        <inertia>
          <ixx>0.000768916188073183</ixx>
          <ixy>-3.91608887242284E-09</ixy>
          <ixz>-1.86122419709981E-08</ixz>
          <iyy>0.00137090251737553</iyy>
          <iyz>-4.72596045124545E-10</iyz>
          <izz>0.000769014346730516</izz>
        </inertia>
      </inertial>
      <visual name='rear_right_wheel_visual'>
                <pose>0 0 0 0 0 0</pose>

        <geometry>
          <mesh>
            <scale>1 1 1</scale>
            <uri>package://rahal_description/meshes/rear_right_wheel.STL</uri>
          </mesh>
        </geometry>
        
        <material>
          <diffuse>0.0 0.0 0.0 1.0</diffuse>
          <ambient>0.0 0.0 0.0 1.0</ambient>
        </material>
      </visual>
      <collision name='rear_right_wheel_collision'>
        <pose>0 0 0 0 0 0</pose>
        <geometry>
          <mesh>
            <scale>1 1 1</scale>
            <uri>package://rahal_description/meshes/rear_right_wheel.STL</uri>
          </mesh>
        </geometry>
      </collision>
    </link>

    <joint name='front_left_wheel_joint' type='revolute'>
                <pose relative_to='front_left_wheel'/>

      <parent>base_link</parent>
      <child>front_left_wheel</child>
      <axis>
        <xyz>0 1 0</xyz>
      </axis>
      <limit>
        <effort>10</effort>
        <velocity>10</velocity>
        <lower>-1.57</lower>
        <upper>1.57</upper>
      </limit>
    </joint>

    <joint name='front_right_wheel_joint' type='revolute'>
       <pose relative_to='front_right_wheel'/>

      <parent>base_link</parent>
      <child>front_right_wheel</child>
      <axis>
        <xyz>0 1 0</xyz>
      </axis>
      <limit>
        <effort>10</effort>
        <velocity>10</velocity>
        <lower>-1.57</lower>
        <upper>1.57</upper>
      </limit>
    </joint>

    <joint name='rear_left_wheel_joint' type='revolute'>
       <pose relative_to='rear_left_wheel'/>

      <parent>base_link</parent>
      <child>rear_left_wheel</child>
      <axis>
        <xyz>0 1 0</xyz>
      </axis>
      <limit>
        <effort>10</effort>
        <velocity>10</velocity>
        <lower>-1.57</lower>
        <upper>1.57</upper>
      </limit>
    </joint>

    <joint name='rear_right_wheel_joint' type='revolute'>
        <pose relative_to='rear_right_wheel'/>
   
      <parent>base_link</parent>
      <child>rear_right_wheel</child>
      <axis>
        <xyz>0 1 0</xyz>
      </axis>
      <limit>
        <effort>10</effort>
        <velocity>10</velocity>
        <lower>-1.57</lower>
        <upper>1.57</upper>
      </limit>
    </joint>


<link name='lidar_link'>
      <pose relative_to='base_link'>0.23529 0 0.085747 0 0 0</pose> 

      <inertial>
        <pose>0 0 0 0 0 0</pose>
        <mass>0.2</mass>
        <inertia>
          <ixx>0.0002</ixx>
          <ixy>0</ixy>
          <ixz>0</ixz>
          <iyy>0.0002</iyy>
          <iyz>0</iyz>
          <izz>0.0002</izz>
        </inertia>
      </inertial>
      <visual name='lidar_visual'>
        <pose>0 0 0 0 0 0</pose>
        <geometry>
          <mesh>
            <scale>1 1 1</scale>
            <uri>package://rahal_description/meshes/lidar_link.STL</uri>
          </mesh>
        </geometry>
        <material>
          <diffuse>0.0 0.0 0.0 1</diffuse>
          <ambient>0.0 0.0 0.0 1</ambient>
        </material>
      </visual>
      <collision name='lidar_collison'>
        <pose>0 0 0  0 0 0</pose>
        <geometry>
          <mesh>
            <scale>1 1 1</scale>
            <uri>package://rahal_description/meshes/lidar_link.STL</uri>
          </mesh>
        </geometry>
      </collision>
 <sensor name="lidar_link" type="gpu_lidar">
        <gz_frame_id>lidar_link</gz_frame_id>
        <topic>scan</topic>
        <update_rate>30</update_rate>
        <lidar>
          <scan>
            <horizontal>
              <samples>2800</samples>
              <resolution>1</resolution>
              <min_angle>-2.356194</min_angle>
              <max_angle>2.356194</max_angle>
            </horizontal>
            <vertical>
              <samples>1</samples>
              <resolution>0.1</resolution>
              <min_angle>0.0</min_angle>
              <max_angle>0.0</max_angle>
            </vertical>
          </scan>
          <range>
            <min>0.15</min>
            <max>25</max>
            <resolution>0.01</resolution>
          </range>
          <frame_id>/lidar_link</frame_id>
        </lidar>
           <always_on>1</always_on>
            <visualize>true</visualize>
      </sensor>
    </link>

    <joint name='base_to_lidar_joint' type='fixed'>
      <parent>base_link</parent>
      <child>lidar_link</child>
    </joint>





    <link name='camera_link'>
  <pose relative_to='base_link'>0.28252 0.0 0.037 0 -0.35 0</pose>
  <inertial>
    <pose>0 0 0 0 0 0</pose>
    <mass>0.15</mass>
    <inertia>
      <ixx>0.00015</ixx>
      <ixy>0</ixy>
      <ixz>0</ixz>
      <iyy>0.00015</iyy>
      <iyz>0</iyz>
      <izz>0.00015</izz>
    </inertia>
  </inertial>
  <visual name='cam_visual'>
    <pose>0 0 0 0 0 0</pose>
    <geometry>
      <box>
        <size>0.02 0.06 0.02</size>
      </box>
    </geometry>
    <material>
      <diffuse>0.2 0.2 0.2 1.0</diffuse>
      <ambient>0.2 0.2 0.2 1.0</ambient>
    </material>
  </visual>
  <collision name='cam_collision'>
    <pose>0 0 0 0 0 0</pose>
    <geometry>
      <box>
        <size>0.02 0.06 0.02</size>
      </box>
    </geometry>
  </collision>
  <sensor name="camera" type="camera">
    <pose>0.28252 0.0 0.029009 0 0 0</pose>
    <camera>
      <horizontal_fov>1.367</horizontal_fov>
      <image>
        <width>640</width>
        <height>480</height>
      </image>
      <clip>
        <near>0.05</near>
        <far>200</far>
      </clip>
    </camera>
    <gz_frame_id>camera_link</gz_frame_id>
    <always_on>1</always_on>
    <update_rate>10</update_rate>
    <visualize>1</visualize>
    <topic>rgb_image</topic>
  </sensor>
</link>


    <joint name='base_to_camera_joint' type='fixed'>
      <parent>base_link</parent>
      <child>camera_link</child>
    </joint>

 <plugin filename="gz-sim-diff-drive-system" name="gz::sim::systems::DiffDrive">
      <left_joint>front_left_wheel_joint</left_joint>
    <left_joint>rear_left_wheel_joint</left_joint>
    <right_joint>front_right_wheel_joint</right_joint>
    <right_joint>rear_right_wheel_joint</right_joint>
    <wheel_separation>0.45</wheel_separation> 
    <wheel_radius>0.09</wheel_radius> 
    <topic>/cmd_vel</topic>
    <odom_frame>odom</odom_frame>
    <robot_base_frame>base_footprint</robot_base_frame>
    <publish_odom>true</publish_odom>
    <publish_odom_tf>true</publish_odom_tf>
    <update_rate>2.5</update_rate>
      <max_linear_acceleration>1</max_linear_acceleration>
      <min_linear_acceleration>-1</min_linear_acceleration>
      <max_angular_acceleration>2</max_angular_acceleration>
      <min_angular_acceleration>-2</min_angular_acceleration>
      <max_linear_velocity>0.5</max_linear_velocity>
      <min_linear_velocity>-0.5</min_linear_velocity>
      <max_angular_velocity>1</max_angular_velocity>
      <min_angular_velocity>-1</min_angular_velocity>
</plugin>

   

<plugin filename="gz-sim-joint-state-publisher-system"
        name="gz::sim::systems::JointStatePublisher">
  <joint_name>front_left_wheel_joint</joint_name>
  <joint_name>front_right_wheel_joint</joint_name>
  <joint_name>rear_left_wheel_joint</joint_name>
  <joint_name>rear_right_wheel_joint</joint_name>
      <update_rate>10</update_rate>

</plugin>

 <plugin filename="ignition-gazebo-odometry-publisher-system"
                name="ignition::gazebo::systems::OdometryPublisher">
            <odom_frame>odom</odom_frame>
            <odom_covariance_topic>odom</odom_covariance_topic>
            <tf_topic>tf</tf_topic>
            <robot_base_frame>base_footprint</robot_base_frame>
            <!-- <odom_publish_frequency>100</odom_publish_frequency> -->
        </plugin>
  </model>
</sdf>
